Workbook

Sheet Assumptions
A1: Municipal Citizen Request Platform — Development Budget
A3: Lean Estimation — Scrum Methodology | Story Points & Velocity-Based Budget
A5: A. TEAM & RATE ASSUMPTIONS (blue cells = inputs you can change)
B6: Role | C6: # People | D6: Weekly Rate (USD) | E6: Sprint Weeks | F6: Sprint Cost (USD) | G6: Notes
B7: Project Manager | C7: 1 | D7: 1800 | E7: 2 | F7: =C7*D7*E7 -> 3600 | G7: Scrum Master / PM hybrid
B8: Frontend Developer | C8: 2 | D8: 1600 | E8: 2 | F8: =C8*D8*E8 -> 6400 | G8: React – Citizen Portal & Admin
B9: Backend Developer | C9: 3 | D9: 1700 | E9: 2 | F9: =C9*D9*E9 -> 10200 | G9: Node/Python microservices
B10: DevOps / Cloud Engineer | C10: 1 | D10: 1900 | E10: 2 | F10: =C10*D10*E10 -> 3800 | G10: AWS/Azure, CI/CD
B11: QA Engineer | C11: 1 | D11: 1400 | E11: 2 | F11: =C11*D11*E11 -> 2800 | G11: Manual + automated testing
B12: UI/UX Designer | C12: 1 | D12: 1500 | E12: 2 | F12: =C12*D12*E12 -> 3000 | G12: Part-time, first 4 sprints only
B13: TOTAL SPRINT COST (per sprint) | F13: =SUM(F7:F12) -> 29800
A15: B. VELOCITY & SPRINT ASSUMPTIONS
B17: Sprint duration (weeks) | C17: 2 | D17: Fixed 2-week sprints
B18: Team velocity (story pts/sprint) | C18: 40 | D18: After ramp-up; first sprint 30 SP
B19: Total story points (backlog) | C19: =Backlog!F46 -> 234 | D19: See Backlog sheet for detail
B20: Buffer / contingency (%) | C20: 0.15 | D20: 15% for unknowns & rework
A22: C. DERIVED BUDGET OUTPUTS
B24: Number of sprints (base) | E24: =CEILING(C19/C18,1) -> 6
B25: Number of sprints (w/ buffer) | E25: =CEILING(C19*(1+C20)/C18,1) -> 7
B26: Project duration (weeks) | E26: =CEILING(C19*(1+C20)/C18,1)*C17 -> 14
B27: BASE LABOR COST | E27: =CEILING(C19/C18,1)*Assumptions!F13 -> 178800
B28: TOTAL BUDGET (w/ buffer) | E28: =CEILING(C19*(1+C20)/C18,1)*Assumptions!F13 -> 208600
B29: Technology & Licenses / yr | E29: 10548
B30: GRAND TOTAL (Labor + Tech) | E30: =CEILING(C19*(1+C20)/C18,1)*Assumptions!F13+E29 -> 219148

Sheet Backlog
A1: Agile Product Backlog — Municipal Citizen Request Platform
A3: # | B3: Epic | C3: User Story | D3: As a… | E3: Priority | F3: SP | G3: Sprint | H3: Acceptance Criteria (summary) | I3: Status
A4: 1 | B4: EP1 Authentication & SSO | C4: US-01 Citizen registration | D4: Citizen | E4: Must Have | F4: 5 | G4: 1 | H4: Email verified; duplicate check; password policy enforced | I4: Pending
A5: 2 | C5: US-02 Citizen login (email/pwd) | D5: Citizen | E5: Must Have | F5: 3 | G5: 1 | H5: JWT issued; locked after 5 failed attempts | I5: Pending
A6: 3 | C6: US-03 Password recovery | D6: Citizen | E6: Must Have | F6: 3 | G6: 1 | H6: Reset link expires in 1hr; new password saved securely | I6: Pending
A7: 4 | C7: US-04 Staff SSO via Gov. Identity Provider | D7: Admin/Staff | E7: Must Have | F7: 8 | G7: 2 | H7: SSO redirects to Gov IdP; session token valid 8hrs | I7: Pending
A8: 5 | C8: US-05 Role-based access control | D8: Admin/Staff | E8: Must Have | F8: 5 | G8: 2 | H8: Citizen / Staff / Supervisor roles enforced at API level | I8: Pending
A9: 6 | B9: EP2 Citizen Request Portal | C9: US-06 Submit new service request | D9: Citizen | E9: Must Have | F9: 8 | G9: 2 | H9: Request saved with unique ID; confirmation shown | I9: Pending
A10: 7 | C10: US-07 Attach photos / documents | D10: Citizen | E10: Must Have | F10: 5 | G10: 3 | H10: Files <10MB accepted; stored in S3; preview shown | I10: Pending
A11: 8 | C11: US-08 Geolocate request on map | D11: Citizen | E11: Must Have | F11: 8 | G11: 3 | H11: Map renders; lat/lng stored; address auto-populated | I11: Pending
A12: 9 | C12: US-09 View request status & history | D12: Citizen | E12: Must Have | F12: 5 | G12: 3 | H12: Timeline shows all status changes with timestamps | I12: Pending
A13: 10 | C13: US-10 Receive email notification on update | D13: Citizen | E13: Must Have | F13: 5 | G13: 4 | H13: Email sent within 2 min of status change | I13: Pending
A14: 11 | C14: US-11 Receive SMS notification | D14: Citizen | E14: Should Have | F14: 3 | G14: 4 | H14: SMS sent via Twilio within 2 min | I14: Pending
A15: 12 | C15: US-12 Search & filter my requests | D15: Citizen | E15: Should Have | F15: 3 | G15: 4 | H15: Filter by status, date range, category; results <1s | I15: Pending
A16: 13 | B16: EP3 Admin Dashboard | C16: US-13 View all incoming requests | D16: Admin/Staff | E16: Must Have | F16: 5 | G16: 2 | H16: Paginated list; sortable columns; real-time refresh | I16: Pending
A17: 14 | C17: US-14 Assign request to department | D17: Admin/Staff | E17: Must Have | F17: 8 | G17: 3 | H17: Dropdown of departments; assignment logged with timestamp | I17: Pending
A18: 15 | C18: US-15 Update request status | D18: Admin/Staff | E18: Must Have | F18: 5 | G18: 3 | H18: Status options: Open / In-Progress / Resolved / Closed | I18: Pending
A19: 16 | C19: US-16 Add internal comments to request | D19: Admin/Staff | E19: Must Have | F19: 3 | G19: 3 | H19: Comment visible only to staff; audit trail kept | I19: Pending
A20: 17 | C20: US-17 Filter & search requests by type/dept/status | D20: Admin/Staff | E20: Should Have | F20: 5 | G20: 4 | H20: Multi-filter; URL-shareable state; <500ms response | I20: Pending
A21: 18 | C21: US-18 View resolution time KPIs | D21: Admin/Staff | E21: Should Have | F21: 8 | G21: 5 | H21: Charts: avg resolution time, open vs closed, by dept | I21: Pending
A22: 19 | C22: US-19 Export requests to CSV/Excel | D22: Admin/Staff | E22: Could Have | F22: 3 | G22: 6 | H22: CSV export reflects current filters; <5s for 10k rows | I22: Pending
A23: 20 | B23: EP4 Reporting & Analytics | C23: US-20 Generate performance report | D23: Admin/Staff | E23: Should Have | F23: 8 | G23: 5 | H23: PDF report generated; date-range selectable | I23: Pending
A24: 21 | C24: US-21 Dashboard charts (requests by type/dept) | D24: Admin/Staff | E24: Should Have | F24: 8 | G24: 5 | H24: Bar/pie charts; monthly trend line; filters applied | I24: Pending
A25: 22 | C25: US-22 Avg. resolution time per department | D25: Admin/Staff | E25: Should Have | F25: 5 | G25: 5 | H25: Table grouped by dept; sortable; benchmark column | I25: Pending
A26: 23 | C26: US-23 Export report as PDF | D26: Admin/Staff | E26: Could Have | F26: 5 | G26: 6 | H26: PDF matches screen; auto-paginated; branded header | I26: Pending
A27: 24 | B27: EP5 Notification Service | C27: US-24 Email notification on request creation | D27: Citizen | E27: Must Have | F27: 3 | G27: 4 | H27: Triggered on creation; template personalised with ID | I27: Pending
A28: 25 | C28: US-25 Email digest for staff (daily summary) | D28: Admin/Staff | E28: Should Have | F28: 5 | G28: 5 | H28: Daily 8AM digest; summarises new + overdue requests | I28: Pending
A29: 26 | C29: US-26 SMS alert for critical request types | D29: Citizen | E29: Could Have | F29: 5 | G29: 6 | H29: High-severity categories trigger SMS within 5 min | I29: Pending
A30: 27 | B30: EP6 File Upload Service | C30: US-27 Upload images up to 10 MB | D30: Citizen | E30: Must Have | F30: 5 | G30: 3 | H30: Progress bar; error shown if >10MB; S3 key returned | I30: Pending
A31: 28 | C31: US-28 Validate file type (jpg, png, pdf) | D31: Citizen | E31: Must Have | F31: 3 | G31: 3 | H31: Reject unsupported MIME types with clear error message | I31: Pending
A32: 29 | C32: US-29 Store files in S3 Object Storage | D32: System | E32: Must Have | F32: 5 | G32: 3 | H32: Files stored under /requests/{id}/; pre-signed URLs | I32: Pending
A33: 30 | C33: US-30 Admin can download attachments | D33: Admin/Staff | E33: Must Have | F33: 3 | G33: 4 | H33: Download link available in request detail; audit logged | I33: Pending
A34: 31 | B34: EP7 Infra & DevOps | C34: US-31 Setup CI/CD pipeline (GitHub Actions) | D34: DevOps | E34: Must Have | F34: 8 | G34: 1 | H34: Pipeline: lint → test → build → deploy on merge to main | I34: Pending
A35: 32 | C35: US-32 Configure cloud hosting (AWS/Azure) | D35: DevOps | E35: Must Have | F35: 8 | G35: 1 | H35: VPC, subnets, security groups configured; SSL cert applied | I35: Pending
A36: 33 | C36: US-33 Setup PostgreSQL & Redis | D36: DevOps | E36: Must Have | F36: 5 | G36: 1 | H36: DB schema migrated; Redis cluster reachable from services | I36: Pending
A37: 34 | C37: US-34 Configure S3 + IAM roles | D37: DevOps | E37: Must Have | F37: 5 | G37: 2 | H37: Bucket policy: private; roles scoped to least privilege | I37: Pending
A38: 35 | C38: US-35 Monitoring & alerting (logs/metrics) | D38: DevOps | E38: Should Have | F38: 8 | G38: 6 | H38: Alerts for >1% 5xx errors and >500ms p95 latency | I38: Pending
A39: 36 | C39: US-36 Load balancer & auto-scaling | D39: DevOps | E39: Should Have | F39: 8 | G39: 6 | H39: Auto-scale triggers at 70% CPU; tested under load | I39: Pending
A40: 37 | B40: EP8 QA & Testing | C40: US-37 Unit tests (>80% coverage) – Auth Service | D40: QA | E40: Must Have | F40: 5 | G40: 2 | H40: Jest/Pytest; CI fails if coverage drops below 80% | I40: Pending
A41: 38 | C41: US-38 Integration tests – API Gateway | D41: QA | E41: Must Have | F41: 5 | G41: 3 | H41: Postman/Newman collection; all endpoints tested | I41: Pending
...

Sheet Sprint Plan
A1: Sprint Plan & Timeline — Municipal Request Platform
A3: Sprint | B3: Weeks | C3: Focus / Theme | D3: Key Stories | E3: SP Target | F3: Cum. SP | G3: Labor Cost (USD)
A4: Sprint 1 | B4: Wk 1-2 | C4: Foundation & Infra | D4: US-31,32,33 CI/CD, Cloud, DB setup; US-01,02,03 Auth basics | E4: =21+5+3+3 -> 32 | F4: =E4 -> 32 | G4: =Assumptions!F13 -> 29800
A5: Sprint 2 | B5: Wk 3-4 | C5: Auth & Core Backend | D5: US-04,05 SSO/RBAC; US-06 Request submission; US-13 Admin list; US-34,37 | E5: =8+5+8+5+5+5 -> 36 | F5: =F4+E5 -> 68 | G5: =Assumptions!F13 -> 29800
A6: Sprint 3 | B6: Wk 5-6 | C6: Citizen Portal MVP | D6: US-07,08,09 Upload/Map/Status; US-14,15,16 Admin ops; US-27,28,29,38 | E6: =5+8+5+8+5+3+5+3+5+5 -> 52 | F6: =F5+E6 -> 120 | G6: =Assumptions!F13 -> 29800
A7: Sprint 4 | B7: Wk 7-8 | C7: Notifications & Refinement | D7: US-10,11,12 Notifications; US-17,24,30 Filters & downloads; US-39 E2E tests | E7: =5+3+3+5+3+3+8 -> 30 | F7: =F6+E7 -> 150 | G7: =Assumptions!F13 -> 29800
A8: Sprint 5 | B8: Wk 9-10 | C8: Analytics & Reporting | D8: US-18,20,21,22 KPIs & charts; US-25 Staff digest | E8: =8+8+8+5+5 -> 34 | F8: =F7+E8 -> 184 | G8: =Assumptions!F13 -> 29800
A9: Sprint 6 | B9: Wk 11-12 | C9: Operations & Hardening | D9: US-19,23,26 Exports; US-35,36 Monitoring/scaling; US-40 Load test | E9: =3+5+5+8+8+8 -> 37 | F9: =F8+E9 -> 221 | G9: =Assumptions!F13 -> 29800
A10: Sprint 7 | B10: Wk 13-14 | C10: UAT & Go-Live Prep | D10: US-41,42 Accessibility & security; regression testing; prod deployment | E10: =8+5 -> 13 | F10: =F9+E10 -> 234 | G10: =Assumptions!F13 -> 29800
A11: TOTAL | E11: =SUM(E4:E10) -> 234 | F11: =SUM(F4:F10) -> 1009 | G11: =SUM(G4:G10) -> 208600

Sheet Tech Costs
A1: Technology & Licensing Costs — Annual Estimate
A3: Category | B3: Service / Tool | C3: Plan / Tier | D3: Monthly Cost (USD) | E3: Annual Cost (USD) | F3: Notes
A4: Cloud Hosting | B4: AWS EC2 / Azure VM (t3.medium × 4) | C4: On-demand | D4: 480 | E4: =D4*12 -> 5760 | F4: Estimate; varies with usage
A5: Cloud Hosting | B5: AWS RDS PostgreSQL (db.t3.medium) | C5: Multi-AZ | D5: 90 | E5: =D5*12 -> 1080 | F5: Estimate; varies with usage
A6: Cloud Hosting | B6: AWS ElastiCache Redis (cache.t3.sm) | C6: Single node | D6: 25 | E6: =D6*12 -> 300 | F6: Estimate; varies with usage
A7: Cloud Hosting | B7: AWS S3 Object Storage (500 GB/mo) | C7: Standard | D7: 12 | E7: =D7*12 -> 144 | F7: Estimate; varies with usage
A8: Cloud Hosting | B8: AWS ALB Load Balancer | C8: Standard | D8: 22 | E8: =D8*12 -> 264 | F8: Estimate; varies with usage
A9: 3rd Party APIs | B9: SendGrid Email API | C9: Essentials | D9: 20 | E9: =D9*12 -> 240 | F9: Estimate; varies with usage
A10: 3rd Party APIs | B10: Twilio SMS | C10: Pay-as-you-go | D10: 30 | E10: =D10*12 -> 360 | F10: Estimate; varies with usage
A11: 3rd Party APIs | B11: Google Maps API | C11: Pay-as-you-go | D11: 50 | E11: =D11*12 -> 600 | F11: Estimate; varies with usage
A12: 3rd Party APIs | B12: Government SSO (IdP) | C12: Public/free | D12: 0 | E12: =D12*12 -> 0 | F12: Estimate; varies with usage
A13: DevOps & Tools | B13: GitHub (Actions + repos) | C13: Team plan | D13: 40 | E13: =D13*12 -> 480 | F13: Estimate; varies with usage
A14: DevOps & Tools | B14: Monitoring (Datadog / CloudWatch) | C14: Pro | D14: 80 | E14: =D14*12 -> 960 | F14: Estimate; varies with usage
A15: DevOps & Tools | B15: Domain & SSL certificate | C15: Annual | D15: 5 | E15: =D15*12 -> 60 | F15: Estimate; varies with usage
... A17: Security | B17: AWS Secrets Manager | C17: Standard | D17: 5 | E17: =D17*12 -> 60 | F17: Estimate; varies with usage
A18: ANNUAL TECHNOLOGY TOTAL | E18: =SUM(E4:E17) -> 10548

Sheet Budget Summary
A1: Development Budget Summary — Municipal Request Platform
B4: Total Story Points | C4: Sprints Required | D4: Project Duration | E4: Team Size
B5: =Backlog!F46 -> 234 | C5: 7 | D5: 14 | E5: =SUM(Assumptions!C7:C12) -> 9
A8: BUDGET BREAKDOWN
A9: Category | B9: Detail | C9: Low Estimate (USD) | D9: Base Estimate (USD) | E9: High Estimate (USD) | F9: % of Total
A10: Labor — Development | B10: 7 sprints × full team | C10: =Assumptions!F13*7*0.85 -> 177310 | D10: =Assumptions!F13*7 -> 208600 | E10: =Assumptions!F13*8 -> 238400 | F10: =IF(SUM(D10:D14)=0,0,D10/SUM(D10:D14)) -> 0.77080547
A11: Technology & Cloud | B11: Annual infra + 3rd-party APIs | C11: ='Tech Costs'!E18*0.8 -> 8438.4 | D11: ='Tech Costs'!E18 -> 10548 | E11: ='Tech Costs'!E18*1.2 -> 12657.6 | F11: =IF(SUM(D10:D14)=0,0,D11/SUM(D10:D14)) -> 0.038976299
A12: QA & Security Audit | B12: External pentest + tools | C12: 3000 | D12: 3500 | E12: 5000 | F12: =IF(SUM(D10:D14)=0,0,D12/SUM(D10:D14)) -> 0.012932978
A13: Contingency (15%) | B13: Buffer for scope changes & rework | C13: =Assumptions!F13*7*0.85*0.1 -> 17731 | D13: =Assumptions!F13*7*0.15 -> 31290 | E13: =Assumptions!F13*8*0.2 -> 47680 | F13: =IF(SUM(D10:D14)=0,0,D13/SUM(D10:D14)) -> 0.11562082
A14: Project Management | B14: PM overhead & stakeholder meetings | C14: =Assumptions!F13*0.05*7 -> 10430 | D14: =Assumptions!F13*0.08*7 -> 16688 | E14: =Assumptions!F13*0.1*8 -> 23840 | F14: =IF(SUM(D10:D14)=0,0,D14/SUM(D10:D14)) -> 0.061664437
A15: GRAND TOTAL | C15: =SUM(C10:C14) -> 216909.4 | D15: =SUM(D10:D14) -> 270626 | E15: =SUM(E10:E14) -> 327577.6 | F15: 1
A17: KEY ASSUMPTIONS • Rates are in USD; team based in Latin America (competitive market rates). • 2-week sprints; velocity of 40 SP/sprint after initial ramp-up (Sprint 1 = 30 SP). • Technology costs are estimated annual figures; actual cloud usage may vary. • 15% contingency applied to labor for scope changes and rework. • Government SSO integration assumes a standard SAML 2.0 / OpenID Connect endpoint is provided at no cost. • Fixed-scope model: backlog is prioritized; if budget is constrained, 'Could Have' stories are deferred.
